Workbook

Sheet Raw_Data_Collection
A1: Ranking | B1: Name | C1: Net worth | D1: Net Worth Expanded | E1: Residence | F1: Moving? (Y/N) | G1: House Price | H1: House Price Source | I1: House Price (Assessed) Year | J1: Total Residential Real Estate | K1: TRRE Price (Assessed) Year(s) | L1: TRRE Source | M1: Notes | N1: Moving Source
A2: 1 | B2: Larry Page | C2: $256.2B | D2: 256200000000 | E2: Palo Alto | F2: Y | G2: 101500000 | H2: https://elmundomiami.com/economy/larry-page-invests-173-4-million-in-the-miami-real-estate-market/ | I2: 2024 | M2: Page's primary residence is now a Florida mansion. | N2: https://www.businessinsider.com/larry-page-leave-california-wealth-billionaire-tax-koop-google-2026-1
A3: 2 | B3: Larry Ellison | C3: $246.1B | D3: 246100000000 | E3: Woodside | F3: Y | G3: 45000000 | H3: https://sfstandard.com/2026/01/05/larry-ellison-san-francisco-home-sale/ | I3: 2025 | M3: Sold property in late 2025. | N3: https://www.sfchronicle.com/california/article/larry-page-larry-ellison-california-wealth-tax-21281843.php
A4: 3 | B4: Sergey Brin | C4: $236.4B | D4: 236400000000 | E4: Los Altos | F4: Y | G4: 35000000 | I4: 2025 | N4: https://www.aol.com/news/google-cofounders-sergey-brin-larry-195211174.html
A5: 4 | B5: Mark Zuckerberg | C5: $225.1B | D5: 225100000000 | E5: Palo Alto | F5: N | G5: 112000000 | H5: https://www.realtor.com/news/celebrity-real-estate/mark-zuckerberg-palo-alto-home-fury-neighbors/ | I5: 2025 | J5: 300000000 | K5: 2011-2025 | L5: https://robbreport.com/shelter/celebrity-homes/mark-zuckerberg-property-portfolio-1236712447/ | M5: Zuckerberg's compund consists of 11 different properties ranging from $5 million to $15 million.
A6: 5 | B6: Jensen Huang | C6: $162.6B | D6: 162600000000 | E6: Los Altos | F6: N | G6: 6900000 | H6: https://www.yahoo.com/lifestyle/articles/3-most-expensive-properties-nvidia-115457861.html | I6: 2025 | J6: 52400000 | K6: 2004 | L6: https://www.foxbusiness.com/lifestyle/nvidias-ceo-extensive-rich-real-estate-portfolio | M6: Huang also has a $38 million San Francisco Mansion. | N6: https://uk.finance.yahoo.com/news/nvidia-jensen-huang-perfectly-fine-170800688.html
A7: 6 | B7: Eric Schmidt | C7: $35.6B | D7: 35600000000 | E7: Los Angeles | F7: N | G7: 110000000 | I7: 2025 | J7: 600000000 | K7: 2025 | L7: https://robbreport.com/shelter/celebrity-homes/lists/eric-schmidt-property-portfolio-1236832435/ | M7: Schmidt also bought a $30.8 million estate in Montecito in 2020.
A8: 7 | B8: Henry Samueli | C8: $32B | D8: 32000000000 | E8: Newport Beach | F8: N | G8: 20150000 | H8: https://www.urbansplatter.com/2024/06/henry-samueli-house-the-california-dwelling/ | I8: 2024 | J8: 20150000 | K8: 2024 | L8: https://www.urbansplatter.com/2024/06/henry-samueli-house-the-california-dwelling/ | M8: Samueli only seems to have one residence.
A9: 8 | B9: Peter Thiel | C9: $26.7B | D9: 26700000000 | E9: Los Angeles | F9: Y | G9: 11500000 | H9: https://labusinessjournal.com/technology/billionaire-peter-thiel-moving-los-angeles/ | I9: 2018 | J9: 77200000 | K9: 2012-2024 | L9: https://www.loveproperty.com/gallerylist/73268/billionaire-boltholes-to-survive-the-end-of-the-world; https://shopoahuproperties.com/paypal-co-founder-peter-thiel-buys-maui-home-for-27m/; https://press.farm/inside-peter-thiels-lifestyle/; https://www.aol.com/news/fords-former-ceo-just-sold-164442537.html; https://press.farm/inside-peter-thiels-lifestyle/ | N9: https://www.forbes.com/sites/tylerroush/2025/12/27/possible-california-wealth-tax-causes-billionaire-freakout-page-thiel-threaten-to-leave/
A10: 9 | B10: Robert Pera | C10: $25.5B | D10: 25500000000 | E10: San Jose | F10: N | G10: 21550000 | H10: https://www.dailymail.co.uk/sport/nba/article-12947653/Memphis-Grizzlies-billionaire-owner-Robert-Pena-Star-Island-arena.html | I10: 2024 | M10: Pera's primary residence is in San Jose, but no sources confirm its value. One of Pera's other residences is a $21.5 million NYC penthouse.
A11: 10 | B11: Adam Foroughi | C11: $25B | D11: 25000000000 | E11: Truckee | F11: N | M11: Homes.com shows Foroughi sold his Truckee home in 2021: https://www.homes.com/property/2413-newhall-ct-truckee-ca/1egj3t32qvw4h/
A12: 11 | B12: Henry Nicholas III | C12: $21.9B | D12: 21900000000 | E12: Newport Coast | F12: N | G12: 19777777 | H12: https://hauteliving.com/2010/01/haute-estate-19-8-million-newport-coast-mansion/18762/ | I12: 2010 | J12: 19777777 | K12: 2010 | L12: https://hauteliving.com/2010/01/haute-estate-19-8-million-newport-coast-mansion/18762/
A13: 12 | B13: John Doerr | C13: $20B | D13: 20000000000 | E13: Woodside | F13: N
A14: 13 | B14: Donald Bren | C14: $19.2B | D14: 19200000000 | E14: Newport Beach | F14: N
A15: 14 | B15: Eric Smidt | C15: $17.9B | D15: 17900000000 | E15: Beverly Hills | F15: N | G15: 54000000 | H15: https://labusinessjournal.com/special-editions/wealthiest-angelenos/wealthiest-2023/10-eric-smidt/ | I15: 2023
A16: 15 | B16: John Tu | C16: $17.5B | D16: 17500000000 | E16: Rolling Hills | F16: N | G16: 7250000 | H16: https://blockshopper.com/ca/los-angeles-county/rolling-hills/property/7567015025/6-east-crest-road | I16: 2011
A17: 16 | B17: David Sun | C17: $17.5B | D17: 17500000000 | E17: Irvine | F17: N
A18: 17 | B18: Jan Koum | C18: $17.1B | D18: 17100000000 | E18: Atherton | F18: Y | G18: 187000000 | H18: https://www.celebritynetworth.com/articles/celebrity-homes/two-years-after-paying-100-million-for-a-malibu-mansion-whatsapp-founder-buys-the-house-next-door-for-87-million/ | I18: 2021 | J18: 400000000 | K18: 2021 | L18: https://www.celebritynetworth.com/articles/billionaire-news/jan-koum-grew-up-on-food-stamps-and-now-owns-more-than-400-million-worth-of-california-real-estate/ | M18: Koum's $187 million compound consists of two houses. | N18: https://nypost.com/2026/01/08/real-estate/tech-titans-leaving-california-for-florida-over-billionaire-tax/
A19: 18 | B19: George Roberts | C19: $15.9B | D19: 15900000000 | E19: Atherton | F19: N | G19: 29084160 | H19: https://blockshopper.com/ca/san-mateo-county/atherton/property/070032440/260-atherton-avenue | I19: 2020
A20: 19 | B20: Laurene Powell Jobs | C20: $14B | D20: 14000000000 | E20: San Francisco | F20: N | G20: 70000000 | H20: https://fortune.com/2024/07/13/laurene-powell-jobs-buys-mansion-san-francisco-billionaires-row-70-million-record-high/ | I20: 2024 | J20: 242000000 | K20: 2015-2024 | L20: https://fortune.com/2024/06/17/laurene-powell-jobs-94-million-malibu-mansion-apple-steve-jobs-widow/; https://www.architecturaldigest.com/story/laurene-powell-jobs-buys-record-breaking-san-francisco-home
A21: 20 | B21: Jack Dangermond | C21: $13.8B | D21: 13800000000 | E21: Redlands | F21: N
A22: 21 | B22: Antony Ressler | C22: $13.1B | D22: 13100000000 | E22: Los Angeles | F22: N | G22: 60000000 | H22: https://www.finance-monthly.com/antony-resslers-net-worth-2025-billionaire-financier-sports-owner-and-philanthropist/ | I22: 2025 | J22: 100000000 | K22: 2025 | L22: https://www.finance-monthly.com/antony-resslers-net-worth-2025-billionaire-financier-sports-owner-and-philanthropist/ | M22: Ressler's various LA properties are estimated to be worth over $100,000,000.
A23: 22 | B23: Vinod Khosla | C23: $12.5B | D23: 12500000000 | E23: Portola Valley | F23: N | G23: 17100579 | H23: https://www.homes.com/property/630-los-trancos-rd-portola-valley-ca/lsj62j03bbdml/ | I23: 2026 | J23: 17100579 | K23: 2026 | L23: https://www.homes.com/property/630-los-trancos-rd-portola-valley-ca/lsj62j03bbdml/ | M23: Estimated value on homes.com is $6,290,000 - $17,100,579, owned by Ltn Trust and Khosla, likely owned by Vinod Khosla secondary source: https://virtualglobetrotting.com/map/vinod-khoslas-house/view/google/
A24: 23 | B24: Riley Bechtel | C24: $11.6B | D24: 11600000000 | E24: Woodside | F24: N | G24: 63300000 | H24: https://www.yahoo.com/entertainment/billionaire-riley-bechtel-pays-record-201404351.html | I24: 2020 | J24: 86100000 | K24: 2011-2020 | L24: https://www.yahoo.com/entertainment/billionaire-riley-bechtel-pays-record-201404351.html
A25: 24 | B25: Dustin Moskovitz | C25: $11.2B | D25: 11200000000 | E25: San Francisco | F25: N | G25: 800000 | H25: https://www.seattletimes.com/business/young-tech-millionaires-keeping-1-bedroom-lifestyle/ | I25: 2011 | M25: Moskovitz' primary residence is an $800,000 San Francisco condo.
A26: 25 | B26: Douglas Leone | C26: $10.7B | D26: 10700000000 | E26: Napa | F26: N | G26: 10000000 | H26: https://www.celebritynetworth.com/richest-businessmen/richest-billionaires/douglas-leone-net-worth/ | I26: 2026 | J26: 80000000 | K26: 2000-2026 | L26: https://www.celebritynetworth.com/richest-businessmen/richest-billionaires/douglas-leone-net-worth/
A27: 26 | B27: Chris Larsen | C27: $10.2B | D27: 10200000000 | E27: San Francisco | F27: N | G27: 13500000 | H27: https://sfstandard.com/2025/09/09/chris-larsen-napa-home/ | I27: 2025 | J27: 13500000 | K27: 2025 | L27: https://docs.google.com/spreadsheets/d/1-d_IAr8tITUy_s8QmIzH-FLYoODzaBxNMWShu9W7IFk/edit?gid=1121030019#gid=1121030019
A28: 27 | B28: Brian Armstrong | C28: $10.1B | D28: 10100000000 | E28: Los Angeles | F28: N | G28: 133000000 | H28: https://www.urbansplatter.com/2022/05/brian-armstrong-house-the-los-angeles-mansion/ | I28: 2022 | J28: 133000000 | K28: 2022 | L28: https://www.urbansplatter.com/2022/05/brian-armstrong-house-the-los-angeles-mansion/
A29: 28 | B29: Marijke Mars | C29: $10B | D29: 10000000000 | E29: Los Angeles | F29: N
A30: 29 | B30: Tom Gores | C30: $10B | D30: 10000000000 | E30: Beverly Hills | F30: N | G30: 100000000 | H30: https://therealdeal.com/la/2016/10/24/platinum-equity-ceo-buys-holmby-hills-spec-home-for-100m/ | I30: 2016 | J30: 138000000 | K30: 2016-2017 | L30: https://therealdeal.com/la/2016/10/24/platinum-equity-ceo-buys-holmby-hills-spec-home-for-100m/; https://therealdeal.com/la/2017/12/04/detroit-pistons-owner-tom-gores-pays-38m-for-his-former-beverly-park-home/
A31: 30 | B31: Andrew Karam | C31: $9.8B | D31: 9800000000 | F31: N
A32: 31 | B32: Brian Chesky | C32: $9.6B | D32: 9600000000 | E32: San Francisco | F32: N | N32: https://www.washingtonpost.com/technology/2026/01/19/california-wealth-tax-exodus/
A33: 32 | B33: Marc Benioff | C33: $9.3B | D33: 9300000000 | E33: San Francisco | F33: N | G33: 18000000 | H33: https://www.yahoo.com/entertainment/twitter-ceo-jack-dorsey-scoops-011751538.html | I33: 2009
A34: 33 | B34: David Geffen | C34: $9.2B | D34: 9200000000 | E34: Beverly Hills | F34: N | G34: 68000000 | H34: https://finance.yahoo.com/news/david-geffen-completes-68-million-192458970.html | I34: 2020 | J34: 132000000 | K34: 2010-2020 | L34: https://www.inman.com/2020/06/11/entertainment-mogul-david-geffen-buys-la-luxury-estate-for-68m/; https://www.forbes.com/sites/erincarlyle/2014/05/07/a-look-at-billionaire-david-geffens-1-1-billion-stash-of-dream-palaces/
A35: 34 | B35: Nathan Blecharczyk | C35: $9.1B | D35: 9100000000 | E35: San Francisco | F35: N
A36: 35 | B36: Lynsi Snyder | C36: $8.6B | D36: 8600000000 | E36: Glendora | F36: Y | M36: Confirmed to be moving, not clear if due to CA Wealth Tax | N36: https://apnews.com/article/innout-ceo-moving-af175b4926847325970b5bcba52276fe
A37: 36 | B37: Steven Rales | C37: $8.6B | D37: 8600000000 | E37: Santa Barbara | F37: N
A38: 37 | B38: Don Hankey | C38: $8.1B | D38: 8100000000 | E38: Malibu | F38: Y | G38: 10659988 | H38: https://www.homes.com/property/27450-pacific-coast-hwy-malibu-ca/gt8keb94hyyzn/ | I38: 2026 | J38: 51300000 | K38: 2021-2026 | L38: https://www.reviewjournal.com/business/housing/l-a-billionaire-buys-summerlin-condo-for-record-high-21m-3609182/; https://therealdeal.com/miami/2021/10/13/billionaire-don-hankey-buys-oceanfront-highland-beach-mansion-for-30m/ | M38: Estimated value on homes.com is $6,882,000 - $19,119,746 | N38: https://www.forbes.com/sites/chasewithorn/2026/01/15/los-angeles-billionaire-moves-to-nevada-after-california-threatens-to-tax-wealth/
A39: 38 | B39: Tench Coxe | C39: $7.8B | D39: 7800000000 | E39: Palo Alto | F39: N | G39: 8683775 | H39: https://www.homes.com/property/1401-emerson-st-palo-alto-ca/znpl6z10qsgvy/ | I39: 2026 | J39: 8683775 | K39: 2026 | L39: https://www.homes.com/property/1401-emerson-st-palo-alto-ca/znpl6z10qsgvy/ | M39: Estimated value on homes.com is $5,573,000 $8,683,775
A40: 39 | B40: Michael Moritz | C40: $7.7B | D40: 7700000000 | E40: San Francisco | F40: N | G40: 10600000 | H40: https://blockshopper.com/ca/san-francisco-county/san-francisco/property/0953006/2626-vallejo-street | I40: 2002 | J40: 10600000 | K40: 2002 | L40: https://blockshopper.com/ca/san-francisco-county/san-francisco/property/0953006/2626-vallejo-street | N40: https://www.bloomberg.com/news/articles/2026-01-08/california-wealth-tax-threat-pushes-billionaires-to-texas-florida
...

Sheet Descriptive_Statistics
D1: Billionaires | E1: Aggregate Wealth | F1: Share of Total
D2: Top 20 | E2: =SUM(Raw_Data_Collection!$D$2:$D$21) -> 1446000000000 | F2: =E2 / SUM(Raw_Data_Collection!$D$2:$D$215) -> 0.67268329
D3: Top 10 | E3: =SUM(Raw_Data_Collection!$D$2:$D$11) -> 1271200000000 | F3: =E3 / SUM(Raw_Data_Collection!$D$2:$D$215) -> 0.59136584
D4: Top 5 | E4: =SUM(Raw_Data_Collection!$D$2:$D$6) -> 1126400000000 | F4: =E4 / SUM(Raw_Data_Collection!$D$2:$D$215) -> 0.52400447
D5: Descriptive Statistics (Billionaire Wealth)
D6: Mean | E6: =AVERAGE(Raw_Data_Collection!$D$2:$D$215) -> 10044859813
D7: Median | E7: =MEDIAN(Raw_Data_Collection!$D$2:$D$215) -> 3150000000
D8: Mode | E8: =MODE(Raw_Data_Collection!$D$2:$D$215) -> 1300000000
D9: Std. Deviation | E9: =Raw_Data_Collection!$D$2:$D$215 -> 26700000000
D10: Max | E10: =MAX(Raw_Data_Collection!$D$2:$D$215) -> 256200000000
D11: Min | E11: =MIN(Raw_Data_Collection!$D$2:$D$215) -> 1000000000
D12: Sum | E12: =SUM(Raw_Data_Collection!$D$2:$D$215) -> 2149600000000
D13: Count | E13: 214
D14: Moving? | E14: Moving Count | F14: Moving Net Worth | G14: Share of Total
D15: Yes | E15: =COUNTIF(Raw_Data_Collection!$F$2:$F$215, "Y") -> 9 | F15: =SUMIF(Raw_Data_Collection!$F$2:$F$215, "Y", Raw_Data_Collection!$D$2:$D$215) -> 806400000000 | G15: =F15 / SUM(Raw_Data_Collection!$D$2:$D$215) -> 0.37513956
D16: No | E16: =COUNTIF(Raw_Data_Collection!$F$2:$F$215, "N") -> 205 | F16: =SUMIF(Raw_Data_Collection!$F$2:$F$215, "N", Raw_Data_Collection!$D$2:$D$215) -> 1343200000000 | G16: =F16 / SUM(Raw_Data_Collection!$D$2:$D$215) -> 0.62486044
D17: Descriptive Statistics (House Price)
D18: Mean | E18: =AVERAGE(Raw_Data_Collection!$G$2:$G$215) -> 33388602
D19: Median | E19: =MEDIAN(Raw_Data_Collection!$G$2:$G$215) -> 15939028
D20: Mode | E20: =MODE(Raw_Data_Collection!$G$2:$G$215) -> 30000000
D21: Std. Deviation | E21: =STDEV(Raw_Data_Collection!$G$2:$G$215) -> 42566696
D22: Max | E22: =MAX(Raw_Data_Collection!$G$2:$G$215) -> 250000000
D23: Min | E23: =MIN(Raw_Data_Collection!$G$2:$G$215) -> 800000
D24: Sum | E24: =SUM(Raw_Data_Collection!$G$2:$G$215) -> 4407295432
D25: Count | E25: =COUNTIF(Raw_Data_Collection!$G$2:$G$215, ">0") -> 132
D26: Descriptive Statistics (Total Res. Real Estate)
D27: Mean | E27: =AVERAGE(Raw_Data_Collection!$J$2:$J$215) -> 64026431
D28: Median | E28: =MEDIAN(Raw_Data_Collection!$J$2:$J$215) -> 19963888
D29: Mode | E29: =MODE(Raw_Data_Collection!$J$2:$J$215) -> 17115689
D30: Std. Deviation | E30: =STDEV(Raw_Data_Collection!$J$2:$J$215) -> 98671832
D31: Max | E31: =MAX(Raw_Data_Collection!$J$2:$J$215) -> 600000000
D32: Min | E32: =MIN(Raw_Data_Collection!$J$2:$J$215) -> 3250000
D33: Sum | E33: =SUM(Raw_Data_Collection!$J$2:$J$215) -> 4737955880
D34: Count | E34: =COUNTIF(Raw_Data_Collection!$J$2:$J$215, ">0") -> 74

Sheet Calculations
O1: 5% One-Time Tax Scenario | R1: 1% One-Time Tax Scenario
A2: Ranking | B2: Name | C2: Net Worth | D2: Net Worth Expanded | E2: Residence | F2: Moving? (Y/N) | G2: House Price | H2: House Price Source | I2: House Price (Assessed) Year | J2: Total Residential Real Estate | K2: Total Residential Real Estate* | L2: Net Worth - TRRE | M2: Capital Gains Rate | N2: Wealth Tax Rate | O2: 5% Wealth Tax Revenues | P2: Cap Gain Initial Calc (5%) | Q2: 5% Capital Gains Revenues | R2: Interest Rate | S2: 1% Wealth Tax Revenues | T2: Cap Gain Initial Calc (1%) | U2: 1% Capital Gains Revenues | V2: TRRE Price (Assessed) Year(s) | W2: TRRE Source | X2: Notes | Y2: Moving Source
A3: 1 | B3: Larry Page | C3: $256.2B | D3: 256200000000 | E3: Palo Alto | F3: =VLOOKUP(B3,Raw_Data_Collection!$B$2:$F$215,5,FALSE) -> Y | G3: =VLOOKUP(B3,Raw_Data_Collection!$B$2:$J$215,6,FALSE) -> 101500000 | H3: https://elmundomiami.com/economy/larry-page-invests-173-4-million-in-the-miami-real-estate-market/ | I3: 2024 | J3: =VLOOKUP(B3,Raw_Data_Collection!$B$2:$J$215,9,FALSE) | K3: =VLOOKUP(B3,Real_Estate_Stats!$A$2:$G$215,7,FALSE) -> 101500000 | L3: =D3-K3 -> 256098500000 | M3: 0.37 | N3: 0.05 | O3: =L3*N3 -> 12804925000 | P3: =O3/(1-M3) -> 20325277778 | Q3: =P3*M3 -> 7520352778 | R3: 0.075 | S3: =L3*N3 + (L3*N3*R3*(4+3+2+1+0)/5) -> 14725663750 | T3: =S3/(1-M3) -> 23374069444 | U3: =T3*M3 -> 8648405694 | X3: Page's primary residence is now a Florida mansion. | Y3: https://www.businessinsider.com/larry-page-leave-california-wealth-billionaire-tax-koop-google-2026-1
A4: 2 | B4: Larry Ellison | C4: $246.1B | D4: 246100000000 | E4: Woodside | F4: =VLOOKUP(B4,Raw_Data_Collection!$B$2:$F$215,5,FALSE) -> Y | G4: =VLOOKUP(B4,Raw_Data_Collection!$B$2:$J$215,6,FALSE) -> 45000000 | H4: https://sfstandard.com/2026/01/05/larry-ellison-san-francisco-home-sale/ | I4: 2025 | J4: =VLOOKUP(B4,Raw_Data_Collection!$B$2:$J$215,9,FALSE) | K4: =VLOOKUP(B4,Real_Estate_Stats!$A$2:$G$215,7,FALSE) -> 45000000 | L4: =D4-K4 -> 246055000000 | M4: 0.37 | N4: 0.05 | O4: =L4*N4 -> 12302750000 | P4: =O4/(1-M4) -> 19528174603 | Q4: =P4*M4 -> 7225424603 | R4: 0.075 | S4: =L4*N4 + (L4*N4*R4*(4+3+2+1+0)/5) -> 14148162500 | T4: =S4/(1-M4) -> 22457400794 | U4: =T4*M4 -> 8309238294 | X4: Sold property in late 2025. | Y4: https://www.sfchronicle.com/california/article/larry-page-larry-ellison-california-wealth-tax-21281843.php
A5: 3 | B5: Sergey Brin | C5: $236.4B | D5: 236400000000 | E5: Los Altos | F5: =VLOOKUP(B5,Raw_Data_Collection!$B$2:$F$215,5,FALSE) -> Y | G5: =VLOOKUP(B5,Raw_Data_Collection!$B$2:$J$215,6,FALSE) -> 35000000 | I5: 2025 | J5: =VLOOKUP(B5,Raw_Data_Collection!$B$2:$J$215,9,FALSE) | K5: =VLOOKUP(B5,Real_Estate_Stats!$A$2:$G$215,7,FALSE) -> 35000000 | L5: =D5-K5 -> 236365000000 | M5: 0.37 | N5: 0.05 | O5: =L5*N5 -> 11818250000 | P5: =O5/(1-M5) -> 18759126984 | Q5: =P5*M5 -> 6940876984 | R5: 0.075 | S5: =L5*N5 + (L5*N5*R5*(4+3+2+1+0)/5) -> 13590987500 | T5: =S5/(1-M5) -> 21572996032 | U5: =T5*M5 -> 7982008532 | Y5: https://www.aol.com/news/google-cofounders-sergey-brin-larry-195211174.html
A6: 4 | B6: Mark Zuckerberg | C6: $225.1B | D6: 225100000000 | E6: Palo Alto | F6: =VLOOKUP(B6,Raw_Data_Collection!$B$2:$F$215,5,FALSE) -> N | G6: =VLOOKUP(B6,Raw_Data_Collection!$B$2:$J$215,6,FALSE) -> 112000000 | H6: https://www.realtor.com/news/celebrity-real-estate/mark-zuckerberg-palo-alto-home-fury-neighbors/ | I6: 2025 | J6: =VLOOKUP(B6,Raw_Data_Collection!$B$2:$J$215,9,FALSE) -> 300000000 | K6: =VLOOKUP(B6,Real_Estate_Stats!$A$2:$G$215,7,FALSE) -> 300000000 | L6: =D6-K6 -> 224800000000 | M6: 0.37 | N6: 0.05 | O6: =L6*N6 -> 11240000000 | P6: =O6/(1-M6) -> 17841269841 | Q6: =P6*M6 -> 6601269841 | R6: 0.075 | S6: =L6*N6 + (L6*N6*R6*(4+3+2+1+0)/5) -> 12926000000 | T6: =S6/(1-M6) -> 20517460317 | U6: =T6*M6 -> 7591460317 | V6: 2011-2025 | W6: https://robbreport.com/shelter/celebrity-homes/mark-zuckerberg-property-portfolio-1236712447/ | X6: Zuckerberg's compund consists of 11 different properties ranging from $5 million to $15 million.
A7: 5 | B7: Jensen Huang | C7: $162.6B | D7: 162600000000 | E7: Los Altos | F7: =VLOOKUP(B7,Raw_Data_Collection!$B$2:$F$215,5,FALSE) -> N | G7: =VLOOKUP(B7,Raw_Data_Collection!$B$2:$J$215,6,FALSE) -> 6900000 | H7: https://www.yahoo.com/lifestyle/articles/3-most-expensive-properties-nvidia-115457861.html | I7: 2025 | J7: =VLOOKUP(B7,Raw_Data_Collection!$B$2:$J$215,9,FALSE) -> 52400000 | K7: =VLOOKUP(B7,Real_Estate_Stats!$A$2:$G$215,7,FALSE) -> 52400000 | L7: =D7-K7 -> 162547600000 | M7: 0.37 | N7: 0.05 | O7: =L7*N7 -> 8127380000 | P7: =O7/(1-M7) -> 12900603175 | Q7: =P7*M7 -> 4773223175 | R7: 0.075 | S7: =L7*N7 + (L7*N7*R7*(4+3+2+1+0)/5) -> 9346487000 | T7: =S7/(1-M7) -> 14835693651 | U7: =T7*M7 -> 5489206651 | V7: 2004 | W7: https://www.foxbusiness.com/lifestyle/nvidias-ceo-extensive-rich-real-estate-portfolio | X7: Huang also has a $38 million San Francisco Mansion. | Y7: https://uk.finance.yahoo.com/news/nvidia-jensen-huang-perfectly-fine-170800688.html
A8: 6 | B8: Eric Schmidt | C8: $35.6B | D8: 35600000000 | E8: Los Angeles | F8: =VLOOKUP(B8,Raw_Data_Collection!$B$2:$F$215,5,FALSE) -> N | G8: =VLOOKUP(B8,Raw_Data_Collection!$B$2:$J$215,6,FALSE) -> 110000000 | I8: 2025 | J8: =VLOOKUP(B8,Raw_Data_Collection!$B$2:$J$215,9,FALSE) -> 600000000 | K8: =VLOOKUP(B8,Real_Estate_Stats!$A$2:$G$215,7,FALSE) -> 600000000 | L8: =D8-K8 -> 35000000000 | M8: 0.37 | N8: 0.05 | O8: =L8*N8 -> 1750000000 | P8: =O8/(1-M8) -> 2777777778 | Q8: =P8*M8 -> 1027777778 | R8: 0.075 | S8: =L8*N8 + (L8*N8*R8*(4+3+2+1+0)/5) -> 2012500000 | T8: =S8/(1-M8) -> 3194444444 | U8: =T8*M8 -> 1181944444 | V8: 2025 | W8: https://robbreport.com/shelter/celebrity-homes/lists/eric-schmidt-property-portfolio-1236832435/ | X8: Schmidt also bought a $30.8 million estate in Montecito in 2020.
A9: 7 | B9: Henry Samueli | C9: $32B | D9: 32000000000 | E9: Newport Beach | F9: =VLOOKUP(B9,Raw_Data_Collection!$B$2:$F$215,5,FALSE) -> N | G9: =VLOOKUP(B9,Raw_Data_Collection!$B$2:$J$215,6,FALSE) -> 20150000 | H9: https://www.urbansplatter.com/2024/06/henry-samueli-house-the-california-dwelling/ | I9: 2024 | J9: =VLOOKUP(B9,Raw_Data_Collection!$B$2:$J$215,9,FALSE) -> 20150000 | K9: =VLOOKUP(B9,Real_Estate_Stats!$A$2:$G$215,7,FALSE) -> 20150000 | L9: =D9-K9 -> 31979850000 | M9: 0.37 | N9: 0.05 | O9: =L9*N9 -> 1598992500 | P9: =O9/(1-M9) -> 2538083333 | Q9: =P9*M9 -> 9.3909083e+08 | R9: 0.075 | S9: =L9*N9 + (L9*N9*R9*(4+3+2+1+0)/5) -> 1838841375 | T9: =S9/(1-M9) -> 2918795833 | U9: =T9*M9 -> 1079954458 | V9: 2024 | W9: https://www.urbansplatter.com/2024/06/henry-samueli-house-the-california-dwelling/ | X9: Samueli only seems to have one residence.
A10: 8 | B10: Peter Thiel | C10: $26.7B | D10: 26700000000 | E10: Los Angeles | F10: =VLOOKUP(B10,Raw_Data_Collection!$B$2:$F$215,5,FALSE) -> Y | G10: =VLOOKUP(B10,Raw_Data_Collection!$B$2:$J$215,6,FALSE) -> 11500000 | H10: https://labusinessjournal.com/technology/billionaire-peter-thiel-moving-los-angeles/ | I10: 2018 | J10: =VLOOKUP(B10,Raw_Data_Collection!$B$2:$J$215,9,FALSE) -> 77200000 | K10: =VLOOKUP(B10,Real_Estate_Stats!$A$2:$G$215,7,FALSE) -> 77200000 | L10: =D10-K10 -> 26622800000 | M10: 0.37 | N10: 0.05 | O10: =L10*N10 -> 1331140000 | P10: =O10/(1-M10) -> 2112920635 | Q10: =P10*M10 -> 7.8178063e+08 | R10: 0.075 | S10: =L10*N10 + (L10*N10*R10*(4+3+2+1+0)/5) -> 1530811000 | T10: =S10/(1-M10) -> 2429858730 | U10: =T10*M10 -> 8.9904773e+08 | V10: 2012-2024 | W10: https://www.loveproperty.com/gallerylist/73268/billionaire-boltholes-to-survive-the-end-of-the-world; https://shopoahuproperties.com/paypal-co-founder-peter-thiel-buys-maui-home-for-27m/; https://press.farm/inside-peter-thiels-lifestyle/; https://www.aol.com/news/fords-former-ceo-just-sold-164442537.html; https://press.farm/inside-peter-thiels-lifestyle/ | Y10: https://www.forbes.com/sites/tylerroush/2025/12/27/possible-california-wealth-tax-causes-billionaire-freakout-page-thiel-threaten-to-leave/
A11: 9 | B11: Robert Pera | C11: $25.5B | D11: 25500000000 | E11: San Jose | F11: =VLOOKUP(B11,Raw_Data_Collection!$B$2:$F$215,5,FALSE) -> N | G11: =VLOOKUP(B11,Raw_Data_Collection!$B$2:$J$215,6,FALSE) -> 21550000 | H11: https://www.dailymail.co.uk/sport/nba/article-12947653/Memphis-Grizzlies-billionaire-owner-Robert-Pena-Star-Island-arena.html | I11: 2024 | J11: =VLOOKUP(B11,Raw_Data_Collection!$B$2:$J$215,9,FALSE) | K11: =VLOOKUP(B11,Real_Estate_Stats!$A$2:$G$215,7,FALSE) -> 21550000 | L11: =D11-K11 -> 25478450000 | M11: 0.37 | N11: 0.05 | O11: =L11*N11 -> 1273922500 | P11: =O11/(1-M11) -> 2022099206 | Q11: =P11*M11 -> 7.4817671e+08 | R11: 0.075 | S11: =L11*N11 + (L11*N11*R11*(4+3+2+1+0)/5) -> 1465010875 | T11: =S11/(1-M11) -> 2325414087 | U11: =T11*M11 -> 8.6040321e+08 | X11: Pera's primary residence is in San Jose, but no sources confirm its value. One of Pera's other residences is a $21.5 million NYC penthouse.
A12: 10 | B12: Adam Foroughi | C12: $25B | D12: 25000000000 | E12: Truckee | F12: =VLOOKUP(B12,Raw_Data_Collection!$B$2:$F$215,5,FALSE) -> N | G12: =VLOOKUP(B12,Raw_Data_Collection!$B$2:$J$215,6,FALSE) | J12: =VLOOKUP(B12,Raw_Data_Collection!$B$2:$J$215,9,FALSE) | K12: =VLOOKUP(B12,Real_Estate_Stats!$A$2:$G$215,7,FALSE) -> 1.5900893e+08 | L12: =D12-K12 -> 24840991071 | M12: 0.37 | N12: 0.05 | O12: =L12*N12 -> 1242049554 | P12: =O12/(1-M12) -> 1971507228 | Q12: =P12*M12 -> 7.2945767e+08 | R12: 0.075 | S12: =L12*N12 + (L12*N12*R12*(4+3+2+1+0)/5) -> 1428356987 | T12: =S12/(1-M12) -> 2267233312 | U12: =T12*M12 -> 8.3887633e+08
A13: 11 | B13: Henry Nicholas III | C13: $21.9B | D13: 21900000000 | E13: Newport Coast | F13: =VLOOKUP(B13,Raw_Data_Collection!$B$2:$F$215,5,FALSE) -> N | G13: =VLOOKUP(B13,Raw_Data_Collection!$B$2:$J$215,6,FALSE) -> 19777777 | H13: https://hauteliving.com/2010/01/haute-estate-19-8-million-newport-coast-mansion/18762/ | I13: 2010 | J13: =VLOOKUP(B13,Raw_Data_Collection!$B$2:$J$215,9,FALSE) -> 19777777 | K13: =VLOOKUP(B13,Real_Estate_Stats!$A$2:$G$215,7,FALSE) -> 19777777 | L13: =D13-K13 -> 21880222223 | M13: 0.37 | N13: 0.05 | O13: =L13*N13 -> 1094011111 | P13: =O13/(1-M13) -> 1736525573 | Q13: =P13*M13 -> 6.4251446e+08 | R13: 0.075 | S13: =L13*N13 + (L13*N13*R13*(4+3+2+1+0)/5) -> 1258112778 | T13: =S13/(1-M13) -> 1997004409 | U13: =T13*M13 -> 7.3889163e+08 | V13: 2010 | W13: https://hauteliving.com/2010/01/haute-estate-19-8-million-newport-coast-mansion/18762/
A14: 12 | B14: John Doerr | C14: $20B | D14: 20000000000 | E14: Woodside | F14: =VLOOKUP(B14,Raw_Data_Collection!$B$2:$F$215,5,FALSE) -> N | G14: =VLOOKUP(B14,Raw_Data_Collection!$B$2:$J$215,6,FALSE) | J14: =VLOOKUP(B14,Raw_Data_Collection!$B$2:$J$215,9,FALSE) | K14: =VLOOKUP(B14,Real_Estate_Stats!$A$2:$G$215,7,FALSE) -> 1.2720714e+08 | L14: =D14-K14 -> 19872792857 | M14: 0.37 | N14: 0.05 | O14: =L14*N14 -> 9.9363964e+08 | P14: =O14/(1-M14) -> 1577205782 | Q14: =P14*M14 -> 5.8356614e+08 | R14: 0.075 | S14: =L14*N14 + (L14*N14*R14*(4+3+2+1+0)/5) -> 1142685589 | T14: =S14/(1-M14) -> 1813786650 | U14: =T14*M14 -> 6.7110106e+08
A15: 13 | B15: Donald Bren | C15: $19.2B | D15: 19200000000 | E15: Newport Beach | F15: =VLOOKUP(B15,Raw_Data_Collection!$B$2:$F$215,5,FALSE) -> N | G15: =VLOOKUP(B15,Raw_Data_Collection!$B$2:$J$215,6,FALSE) | J15: =VLOOKUP(B15,Raw_Data_Collection!$B$2:$J$215,9,FALSE) | K15: =VLOOKUP(B15,Real_Estate_Stats!$A$2:$G$215,7,FALSE) -> 1.2211886e+08 | L15: =D15-K15 -> 19077881143 | M15: 0.37 | N15: 0.05 | O15: =L15*N15 -> 9.5389406e+08 | P15: =O15/(1-M15) -> 1514117551 | Q15: =P15*M15 -> 5.6022349e+08 | R15: 0.075 | S15: =L15*N15 + (L15*N15*R15*(4+3+2+1+0)/5) -> 1096978166 | T15: =S15/(1-M15) -> 1741235184 | U15: =T15*M15 -> 644257018
A16: 14 | B16: Eric Smidt | C16: $17.9B | D16: 17900000000 | E16: Beverly Hills | F16: =VLOOKUP(B16,Raw_Data_Collection!$B$2:$F$215,5,FALSE) -> N | G16: =VLOOKUP(B16,Raw_Data_Collection!$B$2:$J$215,6,FALSE) -> 54000000 | H16: https://labusinessjournal.com/special-editions/wealthiest-angelenos/wealthiest-2023/10-eric-smidt/ | I16: 2023 | J16: =VLOOKUP(B16,Raw_Data_Collection!$B$2:$J$215,9,FALSE) | K16: =VLOOKUP(B16,Real_Estate_Stats!$A$2:$G$215,7,FALSE) -> 54000000 | L16: =D16-K16 -> 17846000000 | M16: 0.37 | N16: 0.05 | O16: =L16*N16 -> 892300000 | P16: =O16/(1-M16) -> 1416349206 | Q16: =P16*M16 -> 5.2404921e+08 | R16: 0.075 | S16: =L16*N16 + (L16*N16*R16*(4+3+2+1+0)/5) -> 1026145000 | T16: =S16/(1-M16) -> 1628801587 | U16: =T16*M16 -> 6.0265659e+08
A17: 15 | B17: John Tu | C17: $17.5B | D17: 17500000000 | E17: Rolling Hills | F17: =VLOOKUP(B17,Raw_Data_Collection!$B$2:$F$215,5,FALSE) -> N | G17: =VLOOKUP(B17,Raw_Data_Collection!$B$2:$J$215,6,FALSE) -> 7250000 | H17: https://blockshopper.com/ca/los-angeles-county/rolling-hills/property/7567015025/6-east-crest-road | I17: 2011 | J17: =VLOOKUP(B17,Raw_Data_Collection!$B$2:$J$215,9,FALSE) | K17: =VLOOKUP(B17,Real_Estate_Stats!$A$2:$G$215,7,FALSE) -> 7250000 | L17: =D17-K17 -> 17492750000 | M17: 0.37 | N17: 0.05 | O17: =L17*N17 -> 874637500 | P17: =O17/(1-M17) -> 1388313492 | Q17: =P17*M17 -> 5.1367599e+08 | R17: 0.075 | S17: =L17*N17 + (L17*N17*R17*(4+3+2+1+0)/5) -> 1005833125 | T17: =S17/(1-M17) -> 1596560516 | U17: =T17*M17 -> 5.9072739e+08
A18: 16 | B18: David Sun | C18: $17.5B | D18: 17500000000 | E18: Irvine | F18: =VLOOKUP(B18,Raw_Data_Collection!$B$2:$F$215,5,FALSE) -> N | G18: =VLOOKUP(B18,Raw_Data_Collection!$B$2:$J$215,6,FALSE) | J18: =VLOOKUP(B18,Raw_Data_Collection!$B$2:$J$215,9,FALSE) | K18: =VLOOKUP(B18,Real_Estate_Stats!$A$2:$G$215,7,FALSE) -> 111306250 | L18: =D18-K18 -> 17388693750 | M18: 0.37 | N18: 0.05 | O18: =L18*N18 -> 8.6943469e+08 | P18: =O18/(1-M18) -> 1380055060 | Q18: =P18*M18 -> 510620372 | R18: 0.075 | S18: =L18*N18 + (L18*N18*R18*(4+3+2+1+0)/5) -> 9.9984989e+08 | T18: =S18/(1-M18) -> 1587063318 | U18: =T18*M18 -> 5.8721343e+08
A19: 17 | B19: Jan Koum | C19: $17.1B | D19: 17100000000 | E19: Atherton | F19: =VLOOKUP(B19,Raw_Data_Collection!$B$2:$F$215,5,FALSE) -> Y | G19: =VLOOKUP(B19,Raw_Data_Collection!$B$2:$J$215,6,FALSE) -> 187000000 | H19: https://www.celebritynetworth.com/articles/celebrity-homes/two-years-after-paying-100-million-for-a-malibu-mansion-whatsapp-founder-buys-the-house-next-door-for-87-million/ | I19: 2021 | J19: =VLOOKUP(B19,Raw_Data_Collection!$B$2:$J$215,9,FALSE) -> 400000000 | K19: =VLOOKUP(B19,Real_Estate_Stats!$A$2:$G$215,7,FALSE) -> 400000000 | L19: =D19-K19 -> 16700000000 | M19: 0.37 | N19: 0.05 | O19: =L19*N19 -> 835000000 | P19: =O19/(1-M19) -> 1325396825 | Q19: =P19*M19 -> 4.9039683e+08 | R19: 0.075 | S19: =L19*N19 + (L19*N19*R19*(4+3+2+1+0)/5) -> 960250000 | T19: =S19/(1-M19) -> 1524206349 | U19: =T19*M19 -> 5.6395635e+08 | V19: 2021 | W19: https://www.celebritynetworth.com/articles/billionaire-news/jan-koum-grew-up-on-food-stamps-and-now-owns-more-than-400-million-worth-of-california-real-estate/ | X19: Koum's $187 million compound consists of two houses. | Y19: https://nypost.com/2026/01/08/real-estate/tech-titans-leaving-california-for-florida-over-billionaire-tax/
A20: 18 | B20: George Roberts | C20: $15.9B | D20: 15900000000 | E20: Atherton | F20: =VLOOKUP(B20,Raw_Data_Collection!$B$2:$F$215,5,FALSE) -> N | G20: =VLOOKUP(B20,Raw_Data_Collection!$B$2:$J$215,6,FALSE) -> 29084160 | H20: https://blockshopper.com/ca/san-mateo-county/atherton/property/070032440/260-atherton-avenue | I20: 2020 | J20: =VLOOKUP(B20,Raw_Data_Collection!$B$2:$J$215,9,FALSE) | K20: =VLOOKUP(B20,Real_Estate_Stats!$A$2:$G$215,7,FALSE) -> 29084160 | L20: =D20-K20 -> 15870915840 | M20: 0.37 | N20: 0.05 | O20: =L20*N20 -> 793545792 | P20: =O20/(1-M20) -> 1259596495 | Q20: =P20*M20 -> 4.660507e+08 | R20: 0.075 | S20: =L20*N20 + (L20*N20*R20*(4+3+2+1+0)/5) -> 9.1257766e+08 | T20: =S20/(1-M20) -> 1448535970 | U20: =T20*M20 -> 5.3595831e+08
A21: 19 | B21: Laurene Powell Jobs | C21: $14B | D21: 14000000000 | E21: San Francisco | F21: =VLOOKUP(B21,Raw_Data_Collection!$B$2:$F$215,5,FALSE) -> N | G21: =VLOOKUP(B21,Raw_Data_Collection!$B$2:$J$215,6,FALSE) -> 70000000 | H21: https://fortune.com/2024/07/13/laurene-powell-jobs-buys-mansion-san-francisco-billionaires-row-70-million-record-high/ | I21: 2024 | J21: =VLOOKUP(B21,Raw_Data_Collection!$B$2:$J$215,9,FALSE) -> 242000000 | K21: =VLOOKUP(B21,Real_Estate_Stats!$A$2:$G$215,7,FALSE) -> 242000000 | L21: =D21-K21 -> 13758000000 | M21: 0.37 | N21: 0.05 | O21: =L21*N21 -> 687900000 | P21: =O21/(1-M21) -> 1091904762 | Q21: =P21*M21 -> 4.0400476e+08 | R21: 0.075 | S21: =L21*N21 + (L21*N21*R21*(4+3+2+1+0)/5) -> 791085000 | T21: =S21/(1-M21) -> 1255690476 | U21: =T21*M21 -> 4.6460548e+08 | V21: 2015-2024 | W21: https://fortune.com/2024/06/17/laurene-powell-jobs-94-million-malibu-mansion-apple-steve-jobs-widow/; https://www.architecturaldigest.com/story/laurene-powell-jobs-buys-record-breaking-san-francisco-home
A22: 20 | B22: Jack Dangermond | C22: $13.8B | D22: 13800000000 | E22: Redlands | F22: =VLOOKUP(B22,Raw_Data_Collection!$B$2:$F$215,5,FALSE) -> N | G22: =VLOOKUP(B22,Raw_Data_Collection!$B$2:$J$215,6,FALSE) | J22: =VLOOKUP(B22,Raw_Data_Collection!$B$2:$J$215,9,FALSE) | K22: =VLOOKUP(B22,Real_Estate_Stats!$A$2:$G$215,7,FALSE) -> 87772929 | L22: =D22-K22 -> 13712227071 | M22: 0.37 | N22: 0.05 | O22: =L22*N22 -> 6.8561135e+08 | P22: =O22/(1-M22) -> 1088271990 | Q22: =P22*M22 -> 4.0266064e+08 | R22: 0.075 | S22: =L22*N22 + (L22*N22*R22*(4+3+2+1+0)/5) -> 7.8845306e+08 | T22: =S22/(1-M22) -> 1251512788 | U22: =T22*M22 -> 4.6305973e+08
A23: 21 | B23: Antony Ressler | C23: $13.1B | D23: 13100000000 | E23: Los Angeles | F23: =VLOOKUP(B23,Raw_Data_Collection!$B$2:$F$215,5,FALSE) -> N | G23: =VLOOKUP(B23,Raw_Data_Collection!$B$2:$J$215,6,FALSE) -> 60000000 | H23: https://www.finance-monthly.com/antony-resslers-net-worth-2025-billionaire-financier-sports-owner-and-philanthropist/ | I23: 2025 | J23: =VLOOKUP(B23,Raw_Data_Collection!$B$2:$J$215,9,FALSE) -> 100000000 | K23: =VLOOKUP(B23,Real_Estate_Stats!$A$2:$G$215,7,FALSE) -> 100000000 | L23: =D23-K23 -> 13000000000 | M23: 0.37 | N23: 0.05 | O23: =L23*N23 -> 650000000 | P23: =O23/(1-M23) -> 1031746032 | Q23: =P23*M23 -> 3.8174603e+08 | R23: 0.075 | S23: =L23*N23 + (L23*N23*R23*(4+3+2+1+0)/5) -> 747500000 | T23: =S23/(1-M23) -> 1186507937 | U23: =T23*M23 -> 4.3900794e+08 | V23: 2025 | W23: https://www.finance-monthly.com/antony-resslers-net-worth-2025-billionaire-financier-sports-owner-and-philanthropist/ | X23: Ressler's various LA properties are estimated to be worth over $100,000,000.
A24: 22 | B24: Vinod Khosla | C24: $12.5B | D24: 12500000000 | E24: Portola Valley | F24: =VLOOKUP(B24,Raw_Data_Collection!$B$2:$F$215,5,FALSE) -> N | G24: =VLOOKUP(B24,Raw_Data_Collection!$B$2:$J$215,6,FALSE) -> 17100579 | J24: =VLOOKUP(B24,Raw_Data_Collection!$B$2:$J$215,9,FALSE) -> 17100579 | K24: =VLOOKUP(B24,Real_Estate_Stats!$A$2:$G$215,7,FALSE) -> 79504464 | L24: =D24-K24 -> 12420495536 | M24: 0.37 | N24: 0.05 | O24: =L24*N24 -> 6.2102478e+08 | P24: =O24/(1-M24) -> 9.8575361e+08 | Q24: =P24*M24 -> 3.6472884e+08 | R24: 0.075 | S24: =L24*N24 + (L24*N24*R24*(4+3+2+1+0)/5) -> 7.1417849e+08 | T24: =S24/(1-M24) -> 1133616656 | U24: =T24*M24 -> 4.1943816e+08
A25: 23 | B25: Riley Bechtel | C25: $11.6B | D25: 11600000000 | E25: Woodside | F25: =VLOOKUP(B25,Raw_Data_Collection!$B$2:$F$215,5,FALSE) -> N | G25: =VLOOKUP(B25,Raw_Data_Collection!$B$2:$J$215,6,FALSE) -> 63300000 | H25: https://www.yahoo.com/entertainment/billionaire-riley-bechtel-pays-record-201404351.html | I25: 2020 | J25: =VLOOKUP(B25,Raw_Data_Collection!$B$2:$J$215,9,FALSE) -> 86100000 | K25: =VLOOKUP(B25,Real_Estate_Stats!$A$2:$G$215,7,FALSE) -> 86100000 | L25: =D25-K25 -> 11513900000 | M25: 0.37 | N25: 0.05 | O25: =L25*N25 -> 575695000 | P25: =O25/(1-M25) -> 9.1380159e+08 | Q25: =P25*M25 -> 3.3810659e+08 | R25: 0.075 | S25: =L25*N25 + (L25*N25*R25*(4+3+2+1+0)/5) -> 662049250 | T25: =S25/(1-M25) -> 1050871825 | U25: =T25*M25 -> 3.8882258e+08 | V25: 2011-2020 | W25: https://www.yahoo.com/entertainment/billionaire-riley-bechtel-pays-record-201404351.html
A26: 24 | B26: Dustin Moskovitz | C26: $11.2B | D26: 11200000000 | E26: San Francisco | F26: =VLOOKUP(B26,Raw_Data_Collection!$B$2:$F$215,5,FALSE) -> N | G26: =VLOOKUP(B26,Raw_Data_Collection!$B$2:$J$215,6,FALSE) -> 800000 | H26: https://www.seattletimes.com/business/young-tech-millionaires-keeping-1-bedroom-lifestyle/ | I26: 2011 | J26: =VLOOKUP(B26,Raw_Data_Collection!$B$2:$J$215,9,FALSE) | K26: =VLOOKUP(B26,Real_Estate_Stats!$A$2:$G$215,7,FALSE) -> 800000 | L26: =D26-K26 -> 11199200000 | M26: 0.37 | N26: 0.05 | O26: =L26*N26 -> 559960000 | P26: =O26/(1-M26) -> 8.888254e+08 | Q26: =P26*M26 -> 3.288654e+08 | R26: 0.075 | S26: =L26*N26 + (L26*N26*R26*(4+3+2+1+0)/5) -> 643954000 | T26: =S26/(1-M26) -> 1022149206 | U26: =T26*M26 -> 3.7819521e+08 | X26: Moskovitz' primary residence is an $800,000 San Francisco condo.
A27: 25 | B27: Douglas Leone | C27: $10.7B | D27: 10700000000 | E27: Napa | F27: =VLOOKUP(B27,Raw_Data_Collection!$B$2:$F$215,5,FALSE) -> N | G27: =VLOOKUP(B27,Raw_Data_Collection!$B$2:$J$215,6,FALSE) -> 10000000 | H27: https://www.celebritynetworth.com/richest-businessmen/richest-billionaires/douglas-leone-net-worth/ | I27: 2026 | J27: =VLOOKUP(B27,Raw_Data_Collection!$B$2:$J$215,9,FALSE) -> 80000000 | K27: =VLOOKUP(B27,Real_Estate_Stats!$A$2:$G$215,7,FALSE) -> 80000000 | L27: =D27-K27 -> 10620000000 | M27: 0.37 | N27: 0.05 | O27: =L27*N27 -> 531000000 | P27: =O27/(1-M27) -> 8.4285714e+08 | Q27: =P27*M27 -> 3.1185714e+08 | R27: 0.075 | S27: =L27*N27 + (L27*N27*R27*(4+3+2+1+0)/5) -> 610650000 | T27: =S27/(1-M27) -> 9.6928571e+08 | U27: =T27*M27 -> 3.5863571e+08 | V27: 2000-2026 | W27: https://www.celebritynetworth.com/richest-businessmen/richest-billionaires/douglas-leone-net-worth/
A28: 26 | B28: Chris Larsen | C28: $10.2B | D28: 10200000000 | E28: San Francisco | F28: =VLOOKUP(B28,Raw_Data_Collection!$B$2:$F$215,5,FALSE) -> N | G28: =VLOOKUP(B28,Raw_Data_Collection!$B$2:$J$215,6,FALSE) -> 13500000 | H28: https://sfstandard.com/2025/09/09/chris-larsen-napa-home/ | I28: 2025 | J28: =VLOOKUP(B28,Raw_Data_Collection!$B$2:$J$215,9,FALSE) -> 13500000 | K28: =VLOOKUP(B28,Real_Estate_Stats!$A$2:$G$215,7,FALSE) -> 13500000 | L28: =D28-K28 -> 10186500000 | M28: 0.37 | N28: 0.05 | O28: =L28*N28 -> 509325000 | P28: =O28/(1-M28) -> 808452381 | Q28: =P28*M28 -> 299127381 | R28: 0.075 | S28: =L28*N28 + (L28*N28*R28*(4+3+2+1+0)/5) -> 585723750 | T28: =S28/(1-M28) -> 9.2972024e+08 | U28: =T28*M28 -> 3.4399649e+08 | V28: 2025 | W28: https://docs.google.com/spreadsheets/d/1-d_IAr8tITUy_s8QmIzH-FLYoODzaBxNMWShu9W7IFk/edit?gid=1121030019#gid=1121030019
A29: 27 | B29: Brian Armstrong | C29: $10.1B | D29: 10100000000 | E29: Los Angeles | F29: =VLOOKUP(B29,Raw_Data_Collection!$B$2:$F$215,5,FALSE) -> N | G29: =VLOOKUP(B29,Raw_Data_Collection!$B$2:$J$215,6,FALSE) -> 133000000 | H29: https://www.urbansplatter.com/2022/05/brian-armstrong-house-the-los-angeles-mansion/ | I29: 2022 | J29: =VLOOKUP(B29,Raw_Data_Collection!$B$2:$J$215,9,FALSE) -> 133000000 | K29: =VLOOKUP(B29,Real_Estate_Stats!$A$2:$G$215,7,FALSE) -> 133000000 | L29: =D29-K29 -> 9967000000 | M29: 0.37 | N29: 0.05 | O29: =L29*N29 -> 498350000 | P29: =O29/(1-M29) -> 791031746 | Q29: =P29*M29 -> 292681746 | R29: 0.075 | S29: =L29*N29 + (L29*N29*R29*(4+3+2+1+0)/5) -> 573102500 | T29: =S29/(1-M29) -> 9.0968651e+08 | U29: =T29*M29 -> 3.3658401e+08 | V29: 2022 | W29: https://www.urbansplatter.com/2022/05/brian-armstrong-house-the-los-angeles-mansion/
A30: 28 | B30: Marijke Mars | C30: $10B | D30: 10000000000 | E30: Los Angeles | F30: =VLOOKUP(B30,Raw_Data_Collection!$B$2:$F$215,5,FALSE) -> N | G30: =VLOOKUP(B30,Raw_Data_Collection!$B$2:$J$215,6,FALSE) | J30: =VLOOKUP(B30,Raw_Data_Collection!$B$2:$J$215,9,FALSE) | K30: =VLOOKUP(B30,Real_Estate_Stats!$A$2:$G$215,7,FALSE) -> 63603571 | L30: =D30-K30 -> 9936396429 | M30: 0.37 | N30: 0.05 | O30: =L30*N30 -> 4.9681982e+08 | P30: =O30/(1-M30) -> 7.8860289e+08 | Q30: =P30*M30 -> 2.9178307e+08 | R30: 0.075 | S30: =L30*N30 + (L30*N30*R30*(4+3+2+1+0)/5) -> 5.7134279e+08 | T30: =S30/(1-M30) -> 9.0689332e+08 | U30: =T30*M30 -> 3.3555053e+08
A31: 29 | B31: Tom Gores | C31: $10B | D31: 10000000000 | E31: Beverly Hills | F31: =VLOOKUP(B31,Raw_Data_Collection!$B$2:$F$215,5,FALSE) -> N | G31: =VLOOKUP(B31,Raw_Data_Collection!$B$2:$J$215,6,FALSE) -> 100000000 | H31: https://therealdeal.com/la/2016/10/24/platinum-equity-ceo-buys-holmby-hills-spec-home-for-100m/ | I31: 2016 | J31: =VLOOKUP(B31,Raw_Data_Collection!$B$2:$J$215,9,FALSE) -> 138000000 | K31: =VLOOKUP(B31,Real_Estate_Stats!$A$2:$G$215,7,FALSE) -> 138000000 | L31: =D31-K31 -> 9862000000 | M31: 0.37 | N31: 0.05 | O31: =L31*N31 -> 493100000 | P31: =O31/(1-M31) -> 7.8269841e+08 | Q31: =P31*M31 -> 2.8959841e+08 | R31: 0.075 | S31: =L31*N31 + (L31*N31*R31*(4+3+2+1+0)/5) -> 567065000 | T31: =S31/(1-M31) -> 9.0010317e+08 | U31: =T31*M31 -> 3.3303817e+08 | V31: 2016-2017 | W31: https://therealdeal.com/la/2016/10/24/platinum-equity-ceo-buys-holmby-hills-spec-home-for-100m/; https://therealdeal.com/la/2017/12/04/detroit-pistons-owner-tom-gores-pays-38m-for-his-former-beverly-park-home/
A32: 30 | B32: Andrew Karam | C32: $9.8B | D32: 9800000000 | F32: =VLOOKUP(B32,Raw_Data_Collection!$B$2:$F$215,5,FALSE) -> N | G32: =VLOOKUP(B32,Raw_Data_Collection!$B$2:$J$215,6,FALSE) | J32: =VLOOKUP(B32,Raw_Data_Collection!$B$2:$J$215,9,FALSE) | K32: =VLOOKUP(B32,Real_Estate_Stats!$A$2:$G$215,7,FALSE) -> 62331500 | L32: =D32-K32 -> 9737668500 | M32: 0.37 | N32: 0.05 | O32: =L32*N32 -> 486883425 | P32: =O32/(1-M32) -> 7.7283083e+08 | Q32: =P32*M32 -> 2.8594741e+08 | R32: 0.075 | S32: =L32*N32 + (L32*N32*R32*(4+3+2+1+0)/5) -> 5.5991594e+08 | T32: =S32/(1-M32) -> 8.8875546e+08 | U32: =T32*M32 -> 3.2883952e+08
A33: 31 | B33: Brian Chesky | C33: $9.6B | D33: 9600000000 | E33: San Francisco | F33: =VLOOKUP(B33,Raw_Data_Collection!$B$2:$F$215,5,FALSE) -> N | G33: =VLOOKUP(B33,Raw_Data_Collection!$B$2:$J$215,6,FALSE) | J33: =VLOOKUP(B33,Raw_Data_Collection!$B$2:$J$215,9,FALSE) | K33: =VLOOKUP(B33,Real_Estate_Stats!$A$2:$G$215,7,FALSE) -> 61059429 | L33: =D33-K33 -> 9538940571 | M33: 0.37 | N33: 0.05 | O33: =L33*N33 -> 4.7694703e+08 | P33: =O33/(1-M33) -> 7.5705878e+08 | Q33: =P33*M33 -> 2.8011175e+08 | R33: 0.075 | S33: =L33*N33 + (L33*N33*R33*(4+3+2+1+0)/5) -> 5.4848908e+08 | T33: =S33/(1-M33) -> 8.7061759e+08 | U33: =T33*M33 -> 322128509 | Y33: https://www.washingtonpost.com/technology/2026/01/19/california-wealth-tax-exodus/
A34: 32 | B34: Marc Benioff | C34: $9.3B | D34: 9300000000 | E34: San Francisco | F34: =VLOOKUP(B34,Raw_Data_Collection!$B$2:$F$215,5,FALSE) -> N | G34: =VLOOKUP(B34,Raw_Data_Collection!$B$2:$J$215,6,FALSE) -> 18000000 | H34: https://www.yahoo.com/entertainment/twitter-ceo-jack-dorsey-scoops-011751538.html | I34: 2009 | J34: =VLOOKUP(B34,Raw_Data_Collection!$B$2:$J$215,9,FALSE) | K34: =VLOOKUP(B34,Real_Estate_Stats!$A$2:$G$215,7,FALSE) -> 18000000 | L34: =D34-K34 -> 9282000000 | M34: 0.37 | N34: 0.05 | O34: =L34*N34 -> 464100000 | P34: =O34/(1-M34) -> 7.3666667e+08 | Q34: =P34*M34 -> 2.7256667e+08 | R34: 0.075 | S34: =L34*N34 + (L34*N34*R34*(4+3+2+1+0)/5) -> 533715000 | T34: =S34/(1-M34) -> 8.4716667e+08 | U34: =T34*M34 -> 3.1345167e+08
A35: 33 | B35: David Geffen | C35: $9.2B | D35: 9200000000 | E35: Beverly Hills | F35: =VLOOKUP(B35,Raw_Data_Collection!$B$2:$F$215,5,FALSE) -> N | G35: =VLOOKUP(B35,Raw_Data_Collection!$B$2:$J$215,6,FALSE) -> 68000000 | H35: https://finance.yahoo.com/news/david-geffen-completes-68-million-192458970.html | I35: 2020 | J35: =VLOOKUP(B35,Raw_Data_Collection!$B$2:$J$215,9,FALSE) -> 132000000 | K35: =VLOOKUP(B35,Real_Estate_Stats!$A$2:$G$215,7,FALSE) -> 132000000 | L35: =D35-K35 -> 9068000000 | M35: 0.37 | N35: 0.05 | O35: =L35*N35 -> 453400000 | P35: =O35/(1-M35) -> 7.1968254e+08 | Q35: =P35*M35 -> 2.6628254e+08 | R35: 0.075 | S35: =L35*N35 + (L35*N35*R35*(4+3+2+1+0)/5) -> 521410000 | T35: =S35/(1-M35) -> 8.2763492e+08 | U35: =T35*M35 -> 3.0622492e+08 | V35: 2010-2020 | W35: https://www.inman.com/2020/06/11/entertainment-mogul-david-geffen-buys-la-luxury-estate-for-68m/; https://www.forbes.com/sites/erincarlyle/2014/05/07/a-look-at-billionaire-david-geffens-1-1-billion-stash-of-dream-palaces/
A36: 34 | B36: Nathan Blecharczyk | C36: $9.1B | D36: 9100000000 | E36: San Francisco | F36: =VLOOKUP(B36,Raw_Data_Collection!$B$2:$F$215,5,FALSE) -> N | G36: =VLOOKUP(B36,Raw_Data_Collection!$B$2:$J$215,6,FALSE) | J36: =VLOOKUP(B36,Raw_Data_Collection!$B$2:$J$215,9,FALSE) | K36: =VLOOKUP(B36,Real_Estate_Stats!$A$2:$G$215,7,FALSE) -> 57879250 | L36: =D36-K36 -> 9042120750 | M36: 0.37 | N36: 0.05 | O36: =L36*N36 -> 4.5210604e+08 | P36: =O36/(1-M36) -> 717628631 | Q36: =P36*M36 -> 2.6552259e+08 | R36: 0.075 | S36: =L36*N36 + (L36*N36*R36*(4+3+2+1+0)/5) -> 5.1992194e+08 | T36: =S36/(1-M36) -> 8.2527293e+08 | U36: =T36*M36 -> 3.0535098e+08
A37: 35 | B37: Lynsi Snyder | C37: $8.6B | D37: 8600000000 | E37: Glendora | F37: =VLOOKUP(B37,Raw_Data_Collection!$B$2:$F$215,5,FALSE) -> Y | G37: =VLOOKUP(B37,Raw_Data_Collection!$B$2:$J$215,6,FALSE) | J37: =VLOOKUP(B37,Raw_Data_Collection!$B$2:$J$215,9,FALSE) | K37: =VLOOKUP(B37,Real_Estate_Stats!$A$2:$G$215,7,FALSE) -> 54699071 | L37: =D37-K37 -> 8545300929 | M37: 0.37 | N37: 0.05 | O37: =L37*N37 -> 4.2726505e+08 | P37: =O37/(1-M37) -> 6.7819849e+08 | Q37: =P37*M37 -> 250933440 | R37: 0.075 | S37: =L37*N37 + (L37*N37*R37*(4+3+2+1+0)/5) -> 4.913548e+08 | T37: =S37/(1-M37) -> 7.7992826e+08 | U37: =T37*M37 -> 288573456 | X37: Confirmed to be moving, not clear if due to CA Wealth Tax | Y37: https://apnews.com/article/innout-ceo-moving-af175b4926847325970b5bcba52276fe
A38: 36 | B38: Steven Rales | C38: $8.6B | D38: 8600000000 | E38: Santa Barbara | F38: =VLOOKUP(B38,Raw_Data_Collection!$B$2:$F$215,5,FALSE) -> N | G38: =VLOOKUP(B38,Raw_Data_Collection!$B$2:$J$215,6,FALSE) | J38: =VLOOKUP(B38,Raw_Data_Collection!$B$2:$J$215,9,FALSE) | K38: =VLOOKUP(B38,Real_Estate_Stats!$A$2:$G$215,7,FALSE) -> 54699071 | L38: =D38-K38 -> 8545300929 | M38: 0.37 | N38: 0.05 | O38: =L38*N38 -> 4.2726505e+08 | P38: =O38/(1-M38) -> 6.7819849e+08 | Q38: =P38*M38 -> 250933440 | R38: 0.075 | S38: =L38*N38 + (L38*N38*R38*(4+3+2+1+0)/5) -> 4.913548e+08 | T38: =S38/(1-M38) -> 7.7992826e+08 | U38: =T38*M38 -> 288573456
A39: 37 | B39: Don Hankey | C39: $8.1B | D39: 8100000000 | E39: Malibu | F39: =VLOOKUP(B39,Raw_Data_Collection!$B$2:$F$215,5,FALSE) -> Y | G39: =VLOOKUP(B39,Raw_Data_Collection!$B$2:$J$215,6,FALSE) -> 10659988 | H39: https://www.homes.com/property/27450-pacific-coast-hwy-malibu-ca/gt8keb94hyyzn/ | I39: 2026 | J39: =VLOOKUP(B39,Raw_Data_Collection!$B$2:$J$215,9,FALSE) -> 51300000 | K39: =VLOOKUP(B39,Real_Estate_Stats!$A$2:$G$215,7,FALSE) -> 51300000 | L39: =D39-K39 -> 8048700000 | M39: 0.37 | N39: 0.05 | O39: =L39*N39 -> 402435000 | P39: =O39/(1-M39) -> 6.3878571e+08 | Q39: =P39*M39 -> 2.3635071e+08 | R39: 0.075 | S39: =L39*N39 + (L39*N39*R39*(4+3+2+1+0)/5) -> 462800250 | T39: =S39/(1-M39) -> 7.3460357e+08 | U39: =T39*M39 -> 2.7180332e+08 | V39: 2021-2026 | W39: https://www.reviewjournal.com/business/housing/l-a-billionaire-buys-summerlin-condo-for-record-high-21m-3609182/; https://therealdeal.com/miami/2021/10/13/billionaire-don-hankey-buys-oceanfront-highland-beach-mansion-for-30m/ | X39: Estimated value on homes.com is $6,882,000 - $19,119,746 | Y39: https://www.forbes.com/sites/chasewithorn/2026/01/15/los-angeles-billionaire-moves-to-nevada-after-california-threatens-to-tax-wealth/
A40: 38 | B40: Tench Coxe | C40: $7.8B | D40: 7800000000 | E40: Palo Alto | F40: =VLOOKUP(B40,Raw_Data_Collection!$B$2:$F$215,5,FALSE) -> N | G40: =VLOOKUP(B40,Raw_Data_Collection!$B$2:$J$215,6,FALSE) -> 8683775 | H40: https://www.homes.com/property/1401-emerson-st-palo-alto-ca/znpl6z10qsgvy/ | I40: 2026 | J40: =VLOOKUP(B40,Raw_Data_Collection!$B$2:$J$215,9,FALSE) -> 8683775 | K40: =VLOOKUP(B40,Real_Estate_Stats!$A$2:$G$215,7,FALSE) -> 8683775 | L40: =D40-K40 -> 7791316225 | M40: 0.37 | N40: 0.05 | O40: =L40*N40 -> 3.8956581e+08 | P40: =O40/(1-M40) -> 6.1835843e+08 | Q40: =P40*M40 -> 2.2879262e+08 | R40: 0.075 | S40: =L40*N40 + (L40*N40*R40*(4+3+2+1+0)/5) -> 4.4800068e+08 | T40: =S40/(1-M40) -> 7.111122e+08 | U40: =T40*M40 -> 2.6311151e+08 | V40: 2026 | W40: https://www.homes.com/property/1401-emerson-st-palo-alto-ca/znpl6z10qsgvy/ | X40: Estimated value on homes.com is $5,573,000 $8,683,775
...

Sheet Real_Estate_Stats
A1: Name | B1: Net Worth Expanded | C1: House Price | D1: Total Residential Real Estate | E1: Real Estate Holdings | F1: % of Net Worth | G1: Adjusted TRRE | H1: Billionaires w/ Identified Real Estate | I1: Using Primary Residence Only | J1: Using Total Reported
A2: Larry Page | B2: 256200000000 | C2: =VLOOKUP(A2,Calculations!$B$3:$K$216,10,FALSE) -> 101500000 | E2: 101500000 | F2: =IF(E2="","",E2/B2) -> 0.00039617486 | G2: =IF(F2="",B2*Summary!$C$22,E2) -> 101500000 | H2: =IF(E2>0,1,0) -> 1 | I2: =IF(AND(C2>0, D2=0), 1, 0) -> 1 | J2: =IF(D2>0,1,0) -> 0
A3: Larry Ellison | B3: 246100000000 | C3: 45000000 | E3: 45000000 | F3: =IF(E3="","",E3/B3) -> 0.0001828525 | G3: =IF(F3="",B3*Summary!$C$22,E3) -> 45000000 | H3: =IF(E3>0,1,0) -> 1 | I3: =IF(AND(C3>0, D3=0), 1, 0) -> 1 | J3: =IF(D3>0,1,0) -> 0
A4: Sergey Brin | B4: 236400000000 | C4: 35000000 | E4: 35000000 | F4: =IF(E4="","",E4/B4) -> 0.00014805415 | G4: =IF(F4="",B4*Summary!$C$22,E4) -> 35000000 | H4: =IF(E4>0,1,0) -> 1 | I4: =IF(AND(C4>0, D4=0), 1, 0) -> 1 | J4: =IF(D4>0,1,0) -> 0
A5: Mark Zuckerberg | B5: 225100000000 | C5: 112000000 | D5: 300000000 | E5: 300000000 | F5: =IF(E5="","",E5/B5) -> 0.001332741 | G5: =IF(F5="",B5*Summary!$C$22,E5) -> 300000000 | H5: =IF(E5>0,1,0) -> 1 | I5: =IF(AND(C5>0, D5=0), 1, 0) -> 0 | J5: =IF(D5>0,1,0) -> 1
A6: Jensen Huang | B6: 162600000000 | C6: 6900000 | D6: 52400000 | E6: 52400000 | F6: =IF(E6="","",E6/B6) -> 0.00032226322 | G6: =IF(F6="",B6*Summary!$C$22,E6) -> 52400000 | H6: =IF(E6>0,1,0) -> 1 | I6: =IF(AND(C6>0, D6=0), 1, 0) -> 0 | J6: =IF(D6>0,1,0) -> 1
A7: Eric Schmidt | B7: 35600000000 | C7: 110000000 | D7: 600000000 | E7: 600000000 | F7: =IF(E7="","",E7/B7) -> 0.016853933 | G7: =IF(F7="",B7*Summary!$C$22,E7) -> 600000000 | H7: =IF(E7>0,1,0) -> 1 | I7: =IF(AND(C7>0, D7=0), 1, 0) -> 0 | J7: =IF(D7>0,1,0) -> 1
A8: Henry Samueli | B8: 32000000000 | C8: 20150000 | D8: 20150000 | E8: 20150000 | F8: =IF(E8="","",E8/B8) -> 0.0006296875 | G8: =IF(F8="",B8*Summary!$C$22,E8) -> 20150000 | H8: =IF(E8>0,1,0) -> 1 | I8: =IF(AND(C8>0, D8=0), 1, 0) -> 0 | J8: =IF(D8>0,1,0) -> 1
A9: Peter Thiel | B9: 26700000000 | C9: 11500000 | D9: 77200000 | E9: 77200000 | F9: =IF(E9="","",E9/B9) -> 0.0028913858 | G9: =IF(F9="",B9*Summary!$C$22,E9) -> 77200000 | H9: =IF(E9>0,1,0) -> 1 | I9: =IF(AND(C9>0, D9=0), 1, 0) -> 0 | J9: =IF(D9>0,1,0) -> 1
A10: Robert Pera | B10: 25500000000 | C10: 21550000 | E10: 21550000 | F10: =IF(E10="","",E10/B10) -> 0.00084509804 | G10: =IF(F10="",B10*Summary!$C$22,E10) -> 21550000 | H10: =IF(E10>0,1,0) -> 1 | I10: =IF(AND(C10>0, D10=0), 1, 0) -> 1 | J10: =IF(D10>0,1,0) -> 0
A11: Adam Foroughi | B11: 25000000000 | F11: =IF(E11="","",E11/B11) | G11: =IF(F11="",B11*Summary!$C$22,E11) -> 1.5900893e+08 | H11: =IF(E11>0,1,0) -> 0 | I11: =IF(AND(C11>0, D11=0), 1, 0) -> 0 | J11: =IF(D11>0,1,0) -> 0
A12: Henry Nicholas III | B12: 21900000000 | C12: 19777777 | D12: 19777777 | E12: 19777777 | F12: =IF(E12="","",E12/B12) -> 0.00090309484 | G12: =IF(F12="",B12*Summary!$C$22,E12) -> 19777777 | H12: =IF(E12>0,1,0) -> 1 | I12: =IF(AND(C12>0, D12=0), 1, 0) -> 0 | J12: =IF(D12>0,1,0) -> 1
A13: John Doerr | B13: 20000000000 | F13: =IF(E13="","",E13/B13) | G13: =IF(F13="",B13*Summary!$C$22,E13) -> 1.2720714e+08 | H13: =IF(E13>0,1,0) -> 0 | I13: =IF(AND(C13>0, D13=0), 1, 0) -> 0 | J13: =IF(D13>0,1,0) -> 0
A14: Donald Bren | B14: 19200000000 | F14: =IF(E14="","",E14/B14) | G14: =IF(F14="",B14*Summary!$C$22,E14) -> 1.2211886e+08 | H14: =IF(E14>0,1,0) -> 0 | I14: =IF(AND(C14>0, D14=0), 1, 0) -> 0 | J14: =IF(D14>0,1,0) -> 0
A15: Eric Smidt | B15: 17900000000 | C15: 54000000 | E15: 54000000 | F15: =IF(E15="","",E15/B15) -> 0.0030167598 | G15: =IF(F15="",B15*Summary!$C$22,E15) -> 54000000 | H15: =IF(E15>0,1,0) -> 1 | I15: =IF(AND(C15>0, D15=0), 1, 0) -> 1 | J15: =IF(D15>0,1,0) -> 0
A16: John Tu | B16: 17500000000 | C16: 7250000 | E16: 7250000 | F16: =IF(E16="","",E16/B16) -> 0.00041428571 | G16: =IF(F16="",B16*Summary!$C$22,E16) -> 7250000 | H16: =IF(E16>0,1,0) -> 1 | I16: =IF(AND(C16>0, D16=0), 1, 0) -> 1 | J16: =IF(D16>0,1,0) -> 0
A17: David Sun | B17: 17500000000 | F17: =IF(E17="","",E17/B17) | G17: =IF(F17="",B17*Summary!$C$22,E17) -> 111306250 | H17: =IF(E17>0,1,0) -> 0 | I17: =IF(AND(C17>0, D17=0), 1, 0) -> 0 | J17: =IF(D17>0,1,0) -> 0
A18: Jan Koum | B18: 17100000000 | C18: 187000000 | D18: 400000000 | E18: 400000000 | F18: =IF(E18="","",E18/B18) -> 0.023391813 | G18: =IF(F18="",B18*Summary!$C$22,E18) -> 400000000 | H18: =IF(E18>0,1,0) -> 1 | I18: =IF(AND(C18>0, D18=0), 1, 0) -> 0 | J18: =IF(D18>0,1,0) -> 1
A19: George Roberts | B19: 15900000000 | C19: 29084160 | E19: 29084160 | F19: =IF(E19="","",E19/B19) -> 0.0018291925 | G19: =IF(F19="",B19*Summary!$C$22,E19) -> 29084160 | H19: =IF(E19>0,1,0) -> 1 | I19: =IF(AND(C19>0, D19=0), 1, 0) -> 1 | J19: =IF(D19>0,1,0) -> 0
A20: Laurene Powell Jobs | B20: 14000000000 | C20: 70000000 | D20: 242000000 | E20: 242000000 | F20: =IF(E20="","",E20/B20) -> 0.017285714 | G20: =IF(F20="",B20*Summary!$C$22,E20) -> 242000000 | H20: =IF(E20>0,1,0) -> 1 | I20: =IF(AND(C20>0, D20=0), 1, 0) -> 0 | J20: =IF(D20>0,1,0) -> 1
A21: Jack Dangermond | B21: 13800000000 | F21: =IF(E21="","",E21/B21) | G21: =IF(F21="",B21*Summary!$C$22,E21) -> 87772929 | H21: =IF(E21>0,1,0) -> 0 | I21: =IF(AND(C21>0, D21=0), 1, 0) -> 0 | J21: =IF(D21>0,1,0) -> 0
A22: Antony Ressler | B22: 13100000000 | C22: 60000000 | D22: 100000000 | E22: 100000000 | F22: =IF(E22="","",E22/B22) -> 0.0076335878 | G22: =IF(F22="",B22*Summary!$C$22,E22) -> 100000000 | H22: =IF(E22>0,1,0) -> 1 | I22: =IF(AND(C22>0, D22=0), 1, 0) -> 0 | J22: =IF(D22>0,1,0) -> 1
A23: Vinod Khosla | B23: 12500000000 | F23: =IF(E23="","",E23/B23) | G23: =IF(F23="",B23*Summary!$C$22,E23) -> 79504464 | H23: =IF(E23>0,1,0) -> 0 | I23: =IF(AND(C23>0, D23=0), 1, 0) -> 0 | J23: =IF(D23>0,1,0) -> 0
A24: Riley Bechtel | B24: 11600000000 | C24: 63300000 | D24: 86100000 | E24: 86100000 | F24: =IF(E24="","",E24/B24) -> 0.0074224138 | G24: =IF(F24="",B24*Summary!$C$22,E24) -> 86100000 | H24: =IF(E24>0,1,0) -> 1 | I24: =IF(AND(C24>0, D24=0), 1, 0) -> 0 | J24: =IF(D24>0,1,0) -> 1
A25: Dustin Moskovitz | B25: 11200000000 | C25: 800000 | E25: 800000 | F25: =IF(E25="","",E25/B25) -> 7.1428571e-05 | G25: =IF(F25="",B25*Summary!$C$22,E25) -> 800000 | H25: =IF(E25>0,1,0) -> 1 | I25: =IF(AND(C25>0, D25=0), 1, 0) -> 1 | J25: =IF(D25>0,1,0) -> 0
A26: Douglas Leone | B26: 10700000000 | C26: 10000000 | D26: 80000000 | E26: 80000000 | F26: =IF(E26="","",E26/B26) -> 0.0074766355 | G26: =IF(F26="",B26*Summary!$C$22,E26) -> 80000000 | H26: =IF(E26>0,1,0) -> 1 | I26: =IF(AND(C26>0, D26=0), 1, 0) -> 0 | J26: =IF(D26>0,1,0) -> 1
A27: Chris Larsen | B27: 10200000000 | C27: 13500000 | D27: 13500000 | E27: 13500000 | F27: =IF(E27="","",E27/B27) -> 0.0013235294 | G27: =IF(F27="",B27*Summary!$C$22,E27) -> 13500000 | H27: =IF(E27>0,1,0) -> 1 | I27: =IF(AND(C27>0, D27=0), 1, 0) -> 0 | J27: =IF(D27>0,1,0) -> 1
A28: Brian Armstrong | B28: 10100000000 | C28: 133000000 | D28: 133000000 | E28: 133000000 | F28: =IF(E28="","",E28/B28) -> 0.013168317 | G28: =IF(F28="",B28*Summary!$C$22,E28) -> 133000000 | H28: =IF(E28>0,1,0) -> 1 | I28: =IF(AND(C28>0, D28=0), 1, 0) -> 0 | J28: =IF(D28>0,1,0) -> 1
A29: Marijke Mars | B29: 10000000000 | F29: =IF(E29="","",E29/B29) | G29: =IF(F29="",B29*Summary!$C$22,E29) -> 63603571 | H29: =IF(E29>0,1,0) -> 0 | I29: =IF(AND(C29>0, D29=0), 1, 0) -> 0 | J29: =IF(D29>0,1,0) -> 0
A30: Tom Gores | B30: 10000000000 | C30: 100000000 | D30: 138000000 | E30: 138000000 | F30: =IF(E30="","",E30/B30) -> 0.0138 | G30: =IF(F30="",B30*Summary!$C$22,E30) -> 138000000 | H30: =IF(E30>0,1,0) -> 1 | I30: =IF(AND(C30>0, D30=0), 1, 0) -> 0 | J30: =IF(D30>0,1,0) -> 1
A31: Andrew Karam | B31: 9800000000 | F31: =IF(E31="","",E31/B31) | G31: =IF(F31="",B31*Summary!$C$22,E31) -> 62331500 | H31: =IF(E31>0,1,0) -> 0 | I31: =IF(AND(C31>0, D31=0), 1, 0) -> 0 | J31: =IF(D31>0,1,0) -> 0
A32: Brian Chesky | B32: 9600000000 | F32: =IF(E32="","",E32/B32) | G32: =IF(F32="",B32*Summary!$C$22,E32) -> 61059429 | H32: =IF(E32>0,1,0) -> 0 | I32: =IF(AND(C32>0, D32=0), 1, 0) -> 0 | J32: =IF(D32>0,1,0) -> 0
A33: Marc Benioff | B33: 9300000000 | C33: 18000000 | E33: 18000000 | F33: =IF(E33="","",E33/B33) -> 0.0019354839 | G33: =IF(F33="",B33*Summary!$C$22,E33) -> 18000000 | H33: =IF(E33>0,1,0) -> 1 | I33: =IF(AND(C33>0, D33=0), 1, 0) -> 1 | J33: =IF(D33>0,1,0) -> 0
A34: David Geffen | B34: 9200000000 | C34: 68000000 | D34: 132000000 | E34: 132000000 | F34: =IF(E34="","",E34/B34) -> 0.014347826 | G34: =IF(F34="",B34*Summary!$C$22,E34) -> 132000000 | H34: =IF(E34>0,1,0) -> 1 | I34: =IF(AND(C34>0, D34=0), 1, 0) -> 0 | J34: =IF(D34>0,1,0) -> 1
A35: Nathan Blecharczyk | B35: 9100000000 | F35: =IF(E35="","",E35/B35) | G35: =IF(F35="",B35*Summary!$C$22,E35) -> 57879250 | H35: =IF(E35>0,1,0) -> 0 | I35: =IF(AND(C35>0, D35=0), 1, 0) -> 0 | J35: =IF(D35>0,1,0) -> 0
A36: Lynsi Snyder | B36: 8600000000 | F36: =IF(E36="","",E36/B36) | G36: =IF(F36="",B36*Summary!$C$22,E36) -> 54699071 | H36: =IF(E36>0,1,0) -> 0 | I36: =IF(AND(C36>0, D36=0), 1, 0) -> 0 | J36: =IF(D36>0,1,0) -> 0
A37: Steven Rales | B37: 8600000000 | F37: =IF(E37="","",E37/B37) | G37: =IF(F37="",B37*Summary!$C$22,E37) -> 54699071 | H37: =IF(E37>0,1,0) -> 0 | I37: =IF(AND(C37>0, D37=0), 1, 0) -> 0 | J37: =IF(D37>0,1,0) -> 0
A38: Don Hankey | B38: 8100000000 | C38: 10659988 | D38: 51300000 | E38: 51300000 | F38: =IF(E38="","",E38/B38) -> 0.0063333333 | G38: =IF(F38="",B38*Summary!$C$22,E38) -> 51300000 | H38: =IF(E38>0,1,0) -> 1 | I38: =IF(AND(C38>0, D38=0), 1, 0) -> 0 | J38: =IF(D38>0,1,0) -> 1
A39: Tench Coxe | B39: 7800000000 | C39: 8683775 | D39: 8683775 | E39: 8683775 | F39: =IF(E39="","",E39/B39) -> 0.0011133045 | G39: =IF(F39="",B39*Summary!$C$22,E39) -> 8683775 | H39: =IF(E39>0,1,0) -> 1 | I39: =IF(AND(C39>0, D39=0), 1, 0) -> 0 | J39: =IF(D39>0,1,0) -> 1
A40: Michael Moritz | B40: 7700000000 | C40: 10600000 | D40: 10600000 | E40: 10600000 | F40: =IF(E40="","",E40/B40) -> 0.0013766234 | G40: =IF(F40="",B40*Summary!$C$22,E40) -> 10600000 | H40: =IF(E40>0,1,0) -> 1 | I40: =IF(AND(C40>0, D40=0), 1, 0) -> 0 | J40: =IF(D40>0,1,0) -> 1
...

Sheet Summary
B2: Wealth Tax Scenarios | J2: Results (Excl. Cap Gains) | N2: 1000000000
C3: W/o Leavers - Revenue Gains ($B) | G3: Leavers - Revenue Gains ($B)
B4: Scenarios | C4: Wealth Tax | E4: Capital Gains | F4: Total | G4: Wealth Tax | H4: Capital Gains | I4: Total | J4: % Change | K4: Wealth Tax | L4: Implied Semi-Elasticity
B5: 5% Tax | C5: =SUM(Calculations!O3:O216)/$C$8 -> 107.03925 | E5: =SUM(Calculations!Q3:Q216)/C8 -> 62.86432 | F5: =SUM(C5:E5) -> 169.90357 | G5: =SUMIF(Calculations!F3:F215,"N",Calculations!O3:O216)/$C$8 -> 66.70863 | H5: =SUMIF(Calculations!F3:F215,"N",Calculations!Q3:Q216)/$C$8 -> 39.178084 | I5: =SUM(G5:H5) -> 105.88671 | J5: =(C5-G5)/C5 -> 0.37678345 | K5: 0.05 | L5: =J5/K5 -> 7.535669
B6: 1% Per Year | C6: =SUM(Calculations!S3:S216)/C8 -> 123.09513 | E6: =SUM(Calculations!U3:U216)/C8 -> 72.293968 | F6: =SUM(C6:E6) -> 195.3891 | G6: =SUMIF(Calculations!F3:F215,"N",Calculations!S3:S216)/$C$8 -> 76.714925 | H6: =SUMIF(Calculations!F3:F215,"N",Calculations!U3:U216)/$C$8 -> 45.054797 | I6: =SUM(G6:H6) -> 121.76972 | J6: =(C6-G6)/C6 -> 0.37678345 | K6: 0.05 | L6: =J6/K6 -> 7.535669
C8: 1000000000
B9: Alt Scenarios | C9: W/o Leavers - Revenue Gains ($B) | G9: Leavers - Revenue Gains ($B) | J9: % Change | K9: Wealth Tax | L9: Implied Semi-Elasticity
B10: Brülhart | C10: 107.04 | G10: =-1*((J10*C10)-C10) -> 51.80736 | J10: =L10*K10 -> 0.516 | K10: 0.05 | L10: 10.32
B11: 1.25x | C11: 107.04 | G11: =-1*((J11*C11)-C11) -> 40.14 | J11: =L11*K11 -> 0.625 | K11: 0.05 | L11: 12.5
B12: 1.5x | C12: 107.04 | G12: =-1*((J12*C12)-C12) -> 26.76 | J12: =L12*K12 -> 0.75 | K12: 0.05 | L12: 15
B14: Type | C14: Y/N | D14: Count | E14: Tot Adj NW ($b) | F14: Prop
